Workbook

Sheet Buchungen
A1: 2025 aqua cloud
A3: Konto/BWA | B3: Datum | C3: Buchungstext | D3: Belegfeld1 | E3: Ausgaben | F3: Einnahmen | G3: Kostenstellen | H3: Leistungsdatum | I3: Kostenstelle
A4: 5900 | B4: 45672 | C4: Technext - Software Engineer 01.2025 | D4: 20240115004 | E4: 1931.99 | G4: 201 | I4: =VLOOKUP(G4,Kostenstellen!$A$1:$C$17,2,0) -> indirekte
A5: 5900 | B5: 45689 | C5: Shevchenko 01.2025 | D5: 010522-250201 | E5: 79.5 | G5: 210 | H5: 45688 | I5: =VLOOKUP(G5,Kostenstellen!$A$1:$C$17,2,0) -> Dev
A6: 5900 | B6: 45689 | C6: Bessmertnyy 01.2025 | D6: 041021-250201 | E6: 2740 | G6: 210 | H6: 45688 | I6: =VLOOKUP(G6,Kostenstellen!$A$1:$C$17,2,0) -> Dev
A7: 5900 | B7: 45689 | C7: Marynkevych 01.2025 | D7: 090124-250201 | E7: 6300 | G7: 210 | H7: 45688 | I7: =VLOOKUP(G7,Kostenstellen!$A$1:$C$17,2,0) -> Dev
A8: 5900 | B8: 45689 | C8: MZA 01.2025 | D8: 091023-250201 | E8: 5000 | G8: 210 | H8: 45688 | I8: =VLOOKUP(G8,Kostenstellen!$A$1:$C$17,2,0) -> Dev
A9: 5900 | B9: 45689 | C9: Madiyar Solutions 01.2025 | D9: 091224-250201 | E9: 3200 | G9: 210 | H9: 45688 | I9: =VLOOKUP(G9,Kostenstellen!$A$1:$C$17,2,0) -> Dev
A10: 5900 | B10: 45689 | C10: Savchenko 01.2025 | D10: 130125-250203 | E10: 2175 | G10: 210 | H10: 45688 | I10: =VLOOKUP(G10,Kostenstellen!$A$1:$C$17,2,0) -> Dev
A11: 5900 | B11: 45689 | C11: Weissgerber 01.2025 | D11: 160924-250201 | E11: 4500 | G11: 210 | H11: 45688 | I11: =VLOOKUP(G11,Kostenstellen!$A$1:$C$17,2,0) -> Dev
A12: 5900 | B12: 45689 | C12: Chebyshev 01.2025 | D12: 201222-250201 | E12: 1200 | G12: 210 | H12: 45688 | I12: =VLOOKUP(G12,Kostenstellen!$A$1:$C$17,2,0) -> Dev
A13: 5900 | B13: 45689 | C13: Shuja 01.2025 | D13: 220701-250201 | E13: 3772 | G13: 210 | H13: 45688 | I13: =VLOOKUP(G13,Kostenstellen!$A$1:$C$17,2,0) -> Dev
A14: 5900 | B14: 45689 | C14: Almasi 01.2025 | D14: 220702-250201 | E14: 4232 | G14: 210 | H14: 45688 | I14: =VLOOKUP(G14,Kostenstellen!$A$1:$C$17,2,0) -> Dev
A15: 5900 | B15: 45689 | C15: Kazymov 01.2025 | D15: 230924-250201 | E15: 2800 | G15: 210 | H15: 45688 | I15: =VLOOKUP(G15,Kostenstellen!$A$1:$C$17,2,0) -> Dev
A16: 5900 | B16: 45689 | C16: Chadin 01.2025 | D16: 25180422-250201 | E16: 1700 | G16: 210 | H16: 45688 | I16: =VLOOKUP(G16,Kostenstellen!$A$1:$C$17,2,0) -> Dev
... A19: 5900 | B19: 45691 | C19: Mykhailov 01.2025 | D19: 060125-250203 | E19: 2454.54 | G19: 220 | H19: 45688 | I19: =VLOOKUP(G19,Kostenstellen!$A$1:$C$17,2,0) -> Product
A20: 5900 | B20: 45692 | C20: andagon people - Schulung | D20: 20252000041 | E20: 3198 | G20: 200 | I20: =VLOOKUP(G20,Kostenstellen!$A$1:$C$17,2,0) -> aqua
A21: 5900 | B21: 45703 | C21: Technext - Software Engineer 02.2025 | D21: 20250215005 | E21: 1925.48 | G21: 201 | I21: =VLOOKUP(G21,Kostenstellen!$A$1:$C$17,2,0) -> indirekte
A22: 5900 | B22: 45717 | C22: Bessmertnyy 02.2025 | D22: 041021-250301 | E22: 2740 | G22: 210 | H22: 45689 | I22: =VLOOKUP(G22,Kostenstellen!$A$1:$C$17,2,0) -> Dev
A23: 5900 | B23: 45717 | C23: Mykhailov 02.2025 | D23: 060125-250301 | E23: 2700 | G23: 220 | H23: 45689 | I23: =VLOOKUP(G23,Kostenstellen!$A$1:$C$17,2,0) -> Product
A24: 5900 | B24: 45717 | C24: Marynkevych 02.2025 | D24: 090124-250301 | E24: 6300 | G24: 210 | H24: 45689 | I24: =VLOOKUP(G24,Kostenstellen!$A$1:$C$17,2,0) -> Dev
A25: 5900 | B25: 45717 | C25: MZA 02.2025 | D25: 091023-250301 | E25: 5000 | G25: 210 | H25: 45716 | I25: =VLOOKUP(G25,Kostenstellen!$A$1:$C$17,2,0) -> Dev
A26: 5900 | B26: 45717 | C26: Madiyar Solutions 02.2025 | D26: 091224-250301 | E26: 3200 | G26: 210 | H26: 45689 | I26: =VLOOKUP(G26,Kostenstellen!$A$1:$C$17,2,0) -> Dev
A27: 5900 | B27: 45717 | C27: Savchenko 02.2025 | D27: 130125-250301 | E27: 2900 | G27: 210 | H27: 45689 | I27: =VLOOKUP(G27,Kostenstellen!$A$1:$C$17,2,0) -> Dev
A28: 5900 | B28: 45717 | C28: Weissgerber 02.2025 | D28: 160924-250301 | E28: 4500 | G28: 210 | H28: 45716 | I28: =VLOOKUP(G28,Kostenstellen!$A$1:$C$17,2,0) -> Dev
A29: 5900 | B29: 45717 | C29: 02.2025 Chebyshev | D29: 201222-250301 | E29: 1200 | G29: 210 | H29: 45716 | I29: =VLOOKUP(G29,Kostenstellen!$A$1:$C$17,2,0) -> Dev
A30: 5900 | B30: 45717 | C30: Shuja 02.2025 | D30: 220701-250301 | E30: 3280 | G30: 210 | H30: 45716 | I30: =VLOOKUP(G30,Kostenstellen!$A$1:$C$17,2,0) -> Dev
A31: 5900 | B31: 45717 | C31: 02.2025 Almasi | D31: 220702-250301 | E31: 3680 | G31: 210 | H31: 45716 | I31: =VLOOKUP(G31,Kostenstellen!$A$1:$C$17,2,0) -> Dev
A32: 5900 | B32: 45717 | C32: Kazymov 02.2025 | D32: 230924-250301 | E32: 2800 | G32: 210 | H32: 45689 | I32: =VLOOKUP(G32,Kostenstellen!$A$1:$C$17,2,0) -> Dev
A33: 5900 | B33: 45717 | C33: Chadin 02.2025 | D33: 25180422-250301 | E33: 1749.7 | G33: 210 | H33: 45689 | I33: =VLOOKUP(G33,Kostenstellen!$A$1:$C$17,2,0) -> Dev
... A35: 5900 | B35: 45717 | C35: Mashynson 02.2025 | D35: 290724-250301 | E35: 2800 | G35: 210 | H35: 45689 | I35: =VLOOKUP(G35,Kostenstellen!$A$1:$C$17,2,0) -> Dev
A36: 5900 | B36: 45730 | C36: andagon people - Schulung 07.2025 | D36: 20252000107 | E36: 1599 | G36: 200 | I36: =VLOOKUP(G36,Kostenstellen!$A$1:$C$17,2,0) -> aqua
A37: 5900 | B37: 45730 | C37: andagon people - Schulung 07.2025 | D37: 20252000108 | E37: 1599 | G37: 200 | I37: =VLOOKUP(G37,Kostenstellen!$A$1:$C$17,2,0) -> aqua
A38: 5900 | B38: 45731 | C38: Technext - Software Engineer 03.2025 | D38: 20250315010 | E38: 1873.27 | G38: 201 | I38: =VLOOKUP(G38,Kostenstellen!$A$1:$C$17,2,0) -> indirekte
A39: 5900 | B39: 45748 | C39: Bessmertnyy 03.2025 | D39: 041021-250401 | E39: 1724 | G39: 210 | H39: 45717 | I39: =VLOOKUP(G39,Kostenstellen!$A$1:$C$17,2,0) -> Dev
A40: 5900 | B40: 45748 | C40: Mykhailov 03.2025 | D40: 060125-250401 | E40: 2700 | G40: 220 | H40: 45717 | I40: =VLOOKUP(G40,Kostenstellen!$A$1:$C$17,2,0) -> Product
A41: 5900 | B41: 45748 | C41: Marynkevych 03.2025 | D41: 090124-250401 | E41: 6300 | G41: 210 | H41: 45717 | I41: =VLOOKUP(G41,Kostenstellen!$A$1:$C$17,2,0) -> Dev
A42: 5900 | B42: 45748 | C42: MZA 03.2025 | D42: 091023-250401 | E42: 5000 | G42: 210 | H42: 45717 | I42: =VLOOKUP(G42,Kostenstellen!$A$1:$C$17,2,0) -> Dev
A43: 5900 | B43: 45748 | C43: Madiyar Solutions 03.2025 | D43: 091224-250401 | E43: 3200 | G43: 210 | H43: 45717 | I43: =VLOOKUP(G43,Kostenstellen!$A$1:$C$17,2,0) -> Dev
A44: 5900 | B44: 45748 | C44: Savchenko 03.2025 | D44: 130125-250401 | E44: 2900 | G44: 210 | H44: 45717 | I44: =VLOOKUP(G44,Kostenstellen!$A$1:$C$17,2,0) -> Dev
...

Sheet BWA
A1: Kanzlei-Rechnungswesen - RW - 358875/10530/2025 / aqua cloud GmbH - [BWA-Nr. 1 - Wertenachweis Kurzfristige Erfolgsrechnung Dezember 2025]
A2: Zeile | B2: Bezeichnung | C2: Konto | E2: Zeile | F2: Konten-/ Zeilenbeschriftung | G2: Dez/2025 _x000D_Konten/Zeilen | H2: BWA-Werte | I2: Jan/2025-Dez/2025 _x000D_Konten/Zeilen | J2: BWA-Werte | K2: Fkt.-Schl.
A3: 1020 | B3: Umsatzerlöse | C3: 4337 | D3: H | F3: Erlöse aus Leistungen nach § 13b UStG | G3: 10330.66 | H3: 188239.89 | I3: 94337.58 | J3: 2187895.4 | K3: 0
A4: 1020 | C4: 4338 | D4: H | F4: Nicht steuerbare Umsätze Drittland | G4: 23132.36 | I4: 188898.92 | K4: 0
A5: 1020 | C5: 4402 | D5: H | F5: Erlöse aqua Miete/SaaS | G5: 68145.25 | I5: 734549.96 | K5: 0
A6: 1020 | C6: 4403 | D6: H | F6: Erlöse 19% USt aqua Kauf | G6: 18327.76 | I6: 372074.58 | K6: 0
A7: 1020 | C7: 4406 | D7: H | F7: Erlöse aqua sonstige | G7: 10000 | I7: 32749 | K7: 0
A8: 1020 | C8: 4409 | D8: H | F8: Erlöse aqua M&S | G8: 58303.86 | I8: 701355.39 | K8: 0
A9: 1020 | C9: 4410 | D9: H | F9: Erlöse Fremdlizenzen | G9: 0 | I9: 63930 | K9: 0
A10: 1020 | C10: 0
A11: 1051 | B11: Gesamtleistung | C11: 0 | E11: 1020 | F11: Umsatzerlöse | G11: 188239.89 | H11: 188239.89 | I11: 2187895.4 | J11: 2187895.4 | K11: 1
A12: 1051 | C12: 0
A13: 1060 | B13: Mat./Wareneinkauf | C13: 5900 | D13: S | F13: Fremdleistungen | G13: 9260 | H13: 9260 | I13: 525900.66 | J13: 612970.67 | K13: 25
A14: 1060 | C14: 5901 | D14: S | F14: Fremdleistund AI | G14: 0 | I14: 36400 | K14: 25
A15: 1060 | C15: 5923 | D15: S | F15: Sonstige Leistungen EU 19% Vorst./USt | G15: 0 | I15: 50670.01 | K15: 25
A16: 1060 | C16: 0
A17: 1080 | B17: Rohertrag | C17: 0 | E17: 1051 | F17: Gesamtleistung | G17: 188239.89 | H17: 178979.89 | I17: 2187895.4 | J17: 1574924.8 | K17: 2
A18: 1080 | C18: 0 | E18: 1060 | F18: Mat./Wareneinkauf | G18: 9260 | I18: 612970.67 | K18: 2
A19: 1080 | C19: 0
A20: 1090 | B20: So. betr. Erlöse | C20: 4830 | D20: H | F20: Sonstige betriebliche Erträge | G20: 0 | H20: 929.85 | I20: 831.67 | J20: 16228.65 | K20: 0
A21: 1090 | C21: 4840 | D21: H | F21: Erträge aus der Währungsumrechnung | G21: 0 | I21: 0.92 | K21: 0
A22: 1090 | C22: 4946 | D22: H | F22: Verrechnete sonstige Sachbezüge | G22: -28 | I22: 4395.65 | K22: 0
A23: 1090 | C23: 4947 | D23: H | F23: Verrech. sonstige Sachbezüge Fzg 19% USt | G23: 957.85 | I23: 11000.41 | K23: 0
A24: 1090 | C24: 0
A25: 1092 | B25: Betriebl. Rohertrag | C25: 0 | E25: 1080 | F25: Rohertrag | G25: 178979.89 | H25: 179909.74 | I25: 1574924.8 | J25: 1591153.4 | K25: 1
A26: 1092 | C26: 0 | E26: 1090 | F26: So. betr. Erlöse | G26: 929.85 | I26: 16228.65 | K26: 1
A27: 1092 | C27: 0
A28: 1100 | B28: Personalkosten | C28: 6020 | D28: S | F28: Gehälter | G28: 41468.6 | H28: 52055.99 | I28: 476397.87 | J28: 606428.88 | K28: 0
A29: 1100 | C29: 6039 | D29: S | F29: Pauschale Steuer für Arbeitnehmer | G29: 0 | I29: 1540.23 | K29: 0
A30: 1100 | C30: 6060 | D30: S | F30: Freiwillige soziale Aufwendung. LSt-pfl. | G30: 0 | I30: 5409.75 | K30: 0
A31: 1100 | C31: 6072 | D31: S | F31: Sachzuwendungen und Dienstleistg. an AN | G31: 559 | I31: 6474 | K31: 0
A32: 1100 | C32: 6090 | D32: S | F32: Fahrtkostenerstatt. Whg./Arbeitsstätte | G32: 29.92 | I32: 241.2 | K32: 0
A33: 1100 | C33: 6110 | D33: S | F33: Gesetzliche Sozialaufwendungen | G33: 8655.1 | I33: 99409.49 | K33: 0
A34: 1100 | C34: 6120 | D34: S | F34: Beiträge zur Berufsgenossenschaft | G34: 0 | I34: 1221.73 | K34: 0
A35: 1100 | C35: 6130 | D35: S | F35: Freiwillige soziale Aufwendung. LSt-frei | G35: 589.37 | I35: 6884.11 | K35: 0
A36: 1100 | C36: 6140 | D36: S | F36: Aufwendungen für Altersversorgung | G36: 754 | I36: 8850.5 | K36: 0
A37: 1100 | C37: 0
A38: 1150 | B38: Versich./Beiträge | C38: 6400 | D38: S | F38: Versicherungen | G38: 509.9 | H38: 8134.82 | I38: 4059.4 | J38: 89299.95 | K38: 0
A39: 1150 | C39: 6420 | D39: S | F39: Beiträge | G39: 0 | I39: 300.56 | K39: 0
A40: 1150 | C40: 6421 | D40: S | F40: HR other | G40: 0 | I40: 2776.91 | K40: 0
...

Sheet Kostenstellen
A1: Kostenstelle/-träger | B1: Kurzbezeichnung | C1: Langbezeichnung | D1: Verantwortlicher
A2: 200 | B2: aqua | C2: Gemeinkosten aqua cloud
A3: 201 | B3: indirekte | C3: inderekte Kosten
A4: 202 | B4: Recruiting | C4: Recruiting
A5: 210 | B5: Dev | C5: Development
A6: 220 | B6: Product | C6: Product
A7: 230 | B7: Sales | C7: Sales
A8: 235 | B8: Marketing | C8: Marketing
A9: 240 | B9: Ranorex | C9: Ranorex
A10: 2001 | B10: Koch Martin | C10: Koch Martin
A11: 2003 | B11: Mann | C11: Mann
A12: 2011 | B12: Elsner | C12: Elsner Paul
A13: 2012 | B13: Weingartz | C13: Weingartz Robert
... A17: 2018 | B17: Ali Lara | C17: Ali Lara
